[2024-02-29 21:34:45,887][0][INFO][color_logger.py:203] Logfile: /data1/xiayuyang/online_mcmt/logs/0_2024-02-29-21-34-45-886619.log
[2024-02-29 21:35:09,467][0][ERROR][generic_smbo.py:275] Exception in objective function:
Traceback (most recent call last):
  File "/data1/xiayuyang/anaconda3/envs/carla/lib/python3.8/site-packages/openbox/utils/limit.py", line 62, in run_without_time_limit
    ret = obj_func(*obj_args, **obj_kwargs)
  File "/data1/xiayuyang/online_mcmt/detector/yolov5/bo.py", line 89, in multi_camera_matching
    accuracy, processing_time, section_json = profile(
  File "/data1/xiayuyang/online_mcmt/detector/yolov5/S13_mcmt.py", line 864, in profile
    mm_data, total_detect_time, total_extract_time, total_sct_time, total_pp_time, total_match_time=run_mtmc(cams_dir=cams_dir_, weights=weights_, imgsz=imgsz_, cams_ratio=cams_ratio_, lazy_threshold=lazy_threshold_)
  File "/data1/xiayuyang/online_mcmt/detector/yolov5/S13_mcmt.py", line 658, in run_mtmc
    frame_nums[cam].append([frame_idx, det_num])
UnboundLocalError: local variable 'det_num' referenced before assignment

config: Configuration(values={
  'fps_camera1': '1',
  'fps_camera2': '1',
  'fps_camera3': '1',
  'fps_camera4': '1',
  'lazy_threshold': 0.7,
  'model_size_camera1': 'yolov5s.pt',
  'model_size_camera2': 'yolov5s.pt',
  'model_size_camera3': 'yolov5s.pt',
  'model_size_camera4': 'yolov5s.pt',
  'resolution_camera1': '320',
  'resolution_camera2': '320',
  'resolution_camera3': '320',
  'resolution_camera4': '320',
})

[2024-02-29 21:35:09,467][0][INFO][generic_smbo.py:295] Iter 1, objectives: [inf, inf].
