[2024-01-18 12:19:40,935][0][INFO][color_logger.py:203] Logfile: /data1/xiayuyang/online_mcmt/logs/0_2024-01-18-12-19-40-934150.log
[2024-01-18 12:19:53,546][0][ERROR][generic_smbo.py:275] Exception in objective function:
Traceback (most recent call last):
  File "/data1/xiayuyang/miniconda3/envs/videoDB/lib/python3.7/site-packages/openbox/utils/limit.py", line 62, in run_without_time_limit
    ret = obj_func(*obj_args, **obj_kwargs)
  File "/data1/xiayuyang/online_mcmt/detector/yolov5/bo.py", line 71, in multi_camera_matching
    cams_dir_= cams_dir, weights_= weights, imgsz_=imgsz, cams_ratio_=cams_ratio, lazy_threshold_=lazy_threshold, gpu_id = GPU_ID)
TypeError: profile() got an unexpected keyword argument 'gpu_id'

config: Configuration(values={
  'fps_camera1': '1',
  'fps_camera2': '1',
  'fps_camera3': '1',
  'fps_camera4': '1',
  'fps_camera5': '1',
  'lazy_threshold': 0.7,
  'model_size_camera1': 'yolov5s.pt',
  'model_size_camera2': 'yolov5s.pt',
  'model_size_camera3': 'yolov5s.pt',
  'model_size_camera4': 'yolov5s.pt',
  'model_size_camera5': 'yolov5s.pt',
  'resolution_camera1': '320',
  'resolution_camera2': '320',
  'resolution_camera3': '320',
  'resolution_camera4': '320',
  'resolution_camera5': '320',
})

[2024-01-18 12:19:53,547][0][INFO][generic_smbo.py:295] Iter 1, objectives: [inf, inf].
