[2024-01-23 23:34:17,303][0][INFO][color_logger.py:203] Logfile: /data1/xiayuyang/online_mcmt/logs/0_2024-01-23-23-34-17-301924.log
[2024-01-23 23:34:48,370][0][ERROR][generic_smbo.py:275] Exception in objective function:
Traceback (most recent call last):
  File "/data1/xiayuyang/anaconda3/envs/carla/lib/python3.8/site-packages/openbox/utils/limit.py", line 62, in run_without_time_limit
    ret = obj_func(*obj_args, **obj_kwargs)
  File "/data1/xiayuyang/online_mcmt/detector/yolov5/bo.py", line 80, in multi_camera_matching
    accuracy, processing_time = profile(
  File "/data1/xiayuyang/online_mcmt/detector/yolov5/my_mtmc.py", line 910, in profile
    gt_detect, gt_dict, total_detect_time, total_extract_time, total_sct_time, total_pp_time, total_match_time=run_mtmc(cams_dir=cams_dir_, weights=weights_, imgsz=imgsz_, cams_ratio=cams_ratio_, lazy_threshold=lazy_threshold_)
  File "/data1/xiayuyang/online_mcmt/detector/yolov5/my_mtmc.py", line 792, in run_mtmc
    g_tid += 1
UnboundLocalError: local variable 'g_tid' referenced before assignment

config: Configuration(values={
  'fps_camera1': '1',
  'fps_camera2': '1',
  'fps_camera3': '1',
  'fps_camera4': '1',
  'fps_camera5': '1',
  'lazy_threshold': 0.7,
  'model_size_camera1': 'yolov5s.pt',
  'model_size_camera2': 'yolov5s.pt',
  'model_size_camera3': 'yolov5s.pt',
  'model_size_camera4': 'yolov5s.pt',
  'model_size_camera5': 'yolov5s.pt',
  'resolution_camera1': '320',
  'resolution_camera2': '320',
  'resolution_camera3': '320',
  'resolution_camera4': '320',
  'resolution_camera5': '320',
})

[2024-01-23 23:34:48,371][0][INFO][generic_smbo.py:295] Iter 1, objectives: [inf, inf].
[2024-01-23 23:35:14,454][0][ERROR][generic_smbo.py:275] Exception in objective function:
Traceback (most recent call last):
  File "/data1/xiayuyang/anaconda3/envs/carla/lib/python3.8/site-packages/openbox/utils/limit.py", line 62, in run_without_time_limit
    ret = obj_func(*obj_args, **obj_kwargs)
  File "/data1/xiayuyang/online_mcmt/detector/yolov5/bo.py", line 80, in multi_camera_matching
    accuracy, processing_time = profile(
  File "/data1/xiayuyang/online_mcmt/detector/yolov5/my_mtmc.py", line 910, in profile
    gt_detect, gt_dict, total_detect_time, total_extract_time, total_sct_time, total_pp_time, total_match_time=run_mtmc(cams_dir=cams_dir_, weights=weights_, imgsz=imgsz_, cams_ratio=cams_ratio_, lazy_threshold=lazy_threshold_)
  File "/data1/xiayuyang/online_mcmt/detector/yolov5/my_mtmc.py", line 792, in run_mtmc
    g_tid += 1
UnboundLocalError: local variable 'g_tid' referenced before assignment

config: Configuration(values={
  'fps_camera1': '10',
  'fps_camera2': '2',
  'fps_camera3': '10',
  'fps_camera4': '10',
  'fps_camera5': '4',
  'lazy_threshold': 0.62,
  'model_size_camera1': 'yolov5m.pt',
  'model_size_camera2': 'yolov5l.pt',
  'model_size_camera3': 'yolov5m.pt',
  'model_size_camera4': 'yolov5l.pt',
  'model_size_camera5': 'yolov5m.pt',
  'resolution_camera1': '1280',
  'resolution_camera2': '640',
  'resolution_camera3': '640',
  'resolution_camera4': '1280',
  'resolution_camera5': '1280',
})

[2024-01-23 23:35:14,455][0][INFO][generic_smbo.py:295] Iter 2, objectives: [inf, inf].
[2024-01-23 23:35:53,898][0][ERROR][generic_smbo.py:275] Exception in objective function:
Traceback (most recent call last):
  File "/data1/xiayuyang/anaconda3/envs/carla/lib/python3.8/site-packages/openbox/utils/limit.py", line 62, in run_without_time_limit
    ret = obj_func(*obj_args, **obj_kwargs)
  File "/data1/xiayuyang/online_mcmt/detector/yolov5/bo.py", line 80, in multi_camera_matching
    accuracy, processing_time = profile(
  File "/data1/xiayuyang/online_mcmt/detector/yolov5/my_mtmc.py", line 910, in profile
    gt_detect, gt_dict, total_detect_time, total_extract_time, total_sct_time, total_pp_time, total_match_time=run_mtmc(cams_dir=cams_dir_, weights=weights_, imgsz=imgsz_, cams_ratio=cams_ratio_, lazy_threshold=lazy_threshold_)
  File "/data1/xiayuyang/online_mcmt/detector/yolov5/my_mtmc.py", line 792, in run_mtmc
    g_tid += 1
UnboundLocalError: local variable 'g_tid' referenced before assignment

config: Configuration(values={
  'fps_camera1': '10',
  'fps_camera2': '10',
  'fps_camera3': '1',
  'fps_camera4': '1',
  'fps_camera5': '1',
  'lazy_threshold': 0.86,
  'model_size_camera1': 'yolov5l.pt',
  'model_size_camera2': 'yolov5m.pt',
  'model_size_camera3': 'yolov5l.pt',
  'model_size_camera4': 'yolov5l.pt',
  'model_size_camera5': 'yolov5m.pt',
  'resolution_camera1': '640',
  'resolution_camera2': '320',
  'resolution_camera3': '1280',
  'resolution_camera4': '320',
  'resolution_camera5': '320',
})

[2024-01-23 23:35:53,899][0][INFO][generic_smbo.py:295] Iter 3, objectives: [inf, inf].
[2024-01-23 23:36:13,597][0][ERROR][generic_smbo.py:275] Exception in objective function:
Traceback (most recent call last):
  File "/data1/xiayuyang/anaconda3/envs/carla/lib/python3.8/site-packages/openbox/utils/limit.py", line 62, in run_without_time_limit
    ret = obj_func(*obj_args, **obj_kwargs)
  File "/data1/xiayuyang/online_mcmt/detector/yolov5/bo.py", line 80, in multi_camera_matching
    accuracy, processing_time = profile(
  File "/data1/xiayuyang/online_mcmt/detector/yolov5/my_mtmc.py", line 910, in profile
    gt_detect, gt_dict, total_detect_time, total_extract_time, total_sct_time, total_pp_time, total_match_time=run_mtmc(cams_dir=cams_dir_, weights=weights_, imgsz=imgsz_, cams_ratio=cams_ratio_, lazy_threshold=lazy_threshold_)
  File "/data1/xiayuyang/online_mcmt/detector/yolov5/my_mtmc.py", line 792, in run_mtmc
    g_tid += 1
UnboundLocalError: local variable 'g_tid' referenced before assignment

config: Configuration(values={
  'fps_camera1': '1',
  'fps_camera2': '10',
  'fps_camera3': '4',
  'fps_camera4': '10',
  'fps_camera5': '10',
  'lazy_threshold': 0.78,
  'model_size_camera1': 'yolov5m.pt',
  'model_size_camera2': 'yolov5s.pt',
  'model_size_camera3': 'yolov5s.pt',
  'model_size_camera4': 'yolov5s.pt',
  'model_size_camera5': 'yolov5l.pt',
  'resolution_camera1': '320',
  'resolution_camera2': '320',
  'resolution_camera3': '1280',
  'resolution_camera4': '320',
  'resolution_camera5': '1280',
})

[2024-01-23 23:36:13,599][0][INFO][generic_smbo.py:295] Iter 4, objectives: [inf, inf].
[2024-01-23 23:36:46,707][0][ERROR][generic_smbo.py:275] Exception in objective function:
Traceback (most recent call last):
  File "/data1/xiayuyang/anaconda3/envs/carla/lib/python3.8/site-packages/openbox/utils/limit.py", line 62, in run_without_time_limit
    ret = obj_func(*obj_args, **obj_kwargs)
  File "/data1/xiayuyang/online_mcmt/detector/yolov5/bo.py", line 80, in multi_camera_matching
    accuracy, processing_time = profile(
  File "/data1/xiayuyang/online_mcmt/detector/yolov5/my_mtmc.py", line 910, in profile
    gt_detect, gt_dict, total_detect_time, total_extract_time, total_sct_time, total_pp_time, total_match_time=run_mtmc(cams_dir=cams_dir_, weights=weights_, imgsz=imgsz_, cams_ratio=cams_ratio_, lazy_threshold=lazy_threshold_)
  File "/data1/xiayuyang/online_mcmt/detector/yolov5/my_mtmc.py", line 792, in run_mtmc
    g_tid += 1
UnboundLocalError: local variable 'g_tid' referenced before assignment

config: Configuration(values={
  'fps_camera1': '2',
  'fps_camera2': '2',
  'fps_camera3': '4',
  'fps_camera4': '1',
  'fps_camera5': '10',
  'lazy_threshold': 0.8999999999999999,
  'model_size_camera1': 'yolov5s.pt',
  'model_size_camera2': 'yolov5s.pt',
  'model_size_camera3': 'yolov5m.pt',
  'model_size_camera4': 'yolov5s.pt',
  'model_size_camera5': 'yolov5l.pt',
  'resolution_camera1': '1280',
  'resolution_camera2': '1280',
  'resolution_camera3': '320',
  'resolution_camera4': '1280',
  'resolution_camera5': '320',
})

[2024-01-23 23:36:46,708][0][INFO][generic_smbo.py:295] Iter 5, objectives: [inf, inf].
[2024-01-23 23:37:15,923][0][ERROR][generic_smbo.py:275] Exception in objective function:
Traceback (most recent call last):
  File "/data1/xiayuyang/anaconda3/envs/carla/lib/python3.8/site-packages/openbox/utils/limit.py", line 62, in run_without_time_limit
    ret = obj_func(*obj_args, **obj_kwargs)
  File "/data1/xiayuyang/online_mcmt/detector/yolov5/bo.py", line 80, in multi_camera_matching
    accuracy, processing_time = profile(
  File "/data1/xiayuyang/online_mcmt/detector/yolov5/my_mtmc.py", line 910, in profile
    gt_detect, gt_dict, total_detect_time, total_extract_time, total_sct_time, total_pp_time, total_match_time=run_mtmc(cams_dir=cams_dir_, weights=weights_, imgsz=imgsz_, cams_ratio=cams_ratio_, lazy_threshold=lazy_threshold_)
  File "/data1/xiayuyang/online_mcmt/detector/yolov5/my_mtmc.py", line 792, in run_mtmc
    g_tid += 1
UnboundLocalError: local variable 'g_tid' referenced before assignment

config: Configuration(values={
  'fps_camera1': '1',
  'fps_camera2': '2',
  'fps_camera3': '4',
  'fps_camera4': '4',
  'fps_camera5': '1',
  'lazy_threshold': 0.7,
  'model_size_camera1': 'yolov5l.pt',
  'model_size_camera2': 'yolov5l.pt',
  'model_size_camera3': 'yolov5l.pt',
  'model_size_camera4': 'yolov5m.pt',
  'model_size_camera5': 'yolov5m.pt',
  'resolution_camera1': '320',
  'resolution_camera2': '1280',
  'resolution_camera3': '1280',
  'resolution_camera4': '640',
  'resolution_camera5': '320',
})

[2024-01-23 23:37:15,924][0][INFO][generic_smbo.py:295] Iter 6, objectives: [inf, inf].
[2024-01-23 23:37:52,456][0][ERROR][generic_smbo.py:275] Exception in objective function:
Traceback (most recent call last):
  File "/data1/xiayuyang/anaconda3/envs/carla/lib/python3.8/site-packages/openbox/utils/limit.py", line 62, in run_without_time_limit
    ret = obj_func(*obj_args, **obj_kwargs)
  File "/data1/xiayuyang/online_mcmt/detector/yolov5/bo.py", line 80, in multi_camera_matching
    accuracy, processing_time = profile(
  File "/data1/xiayuyang/online_mcmt/detector/yolov5/my_mtmc.py", line 910, in profile
    gt_detect, gt_dict, total_detect_time, total_extract_time, total_sct_time, total_pp_time, total_match_time=run_mtmc(cams_dir=cams_dir_, weights=weights_, imgsz=imgsz_, cams_ratio=cams_ratio_, lazy_threshold=lazy_threshold_)
  File "/data1/xiayuyang/online_mcmt/detector/yolov5/my_mtmc.py", line 792, in run_mtmc
    g_tid += 1
UnboundLocalError: local variable 'g_tid' referenced before assignment

config: Configuration(values={
  'fps_camera1': '10',
  'fps_camera2': '1',
  'fps_camera3': '1',
  'fps_camera4': '1',
  'fps_camera5': '2',
  'lazy_threshold': 0.6799999999999999,
  'model_size_camera1': 'yolov5s.pt',
  'model_size_camera2': 'yolov5l.pt',
  'model_size_camera3': 'yolov5l.pt',
  'model_size_camera4': 'yolov5s.pt',
  'model_size_camera5': 'yolov5s.pt',
  'resolution_camera1': '320',
  'resolution_camera2': '1280',
  'resolution_camera3': '640',
  'resolution_camera4': '640',
  'resolution_camera5': '1280',
})

[2024-01-23 23:37:52,457][0][INFO][generic_smbo.py:295] Iter 7, objectives: [inf, inf].
[2024-01-23 23:38:20,158][0][ERROR][generic_smbo.py:275] Exception in objective function:
Traceback (most recent call last):
  File "/data1/xiayuyang/anaconda3/envs/carla/lib/python3.8/site-packages/openbox/utils/limit.py", line 62, in run_without_time_limit
    ret = obj_func(*obj_args, **obj_kwargs)
  File "/data1/xiayuyang/online_mcmt/detector/yolov5/bo.py", line 80, in multi_camera_matching
    accuracy, processing_time = profile(
  File "/data1/xiayuyang/online_mcmt/detector/yolov5/my_mtmc.py", line 910, in profile
    gt_detect, gt_dict, total_detect_time, total_extract_time, total_sct_time, total_pp_time, total_match_time=run_mtmc(cams_dir=cams_dir_, weights=weights_, imgsz=imgsz_, cams_ratio=cams_ratio_, lazy_threshold=lazy_threshold_)
  File "/data1/xiayuyang/online_mcmt/detector/yolov5/my_mtmc.py", line 792, in run_mtmc
    g_tid += 1
UnboundLocalError: local variable 'g_tid' referenced before assignment

config: Configuration(values={
  'fps_camera1': '4',
  'fps_camera2': '4',
  'fps_camera3': '1',
  'fps_camera4': '10',
  'fps_camera5': '2',
  'lazy_threshold': 0.8,
  'model_size_camera1': 'yolov5m.pt',
  'model_size_camera2': 'yolov5m.pt',
  'model_size_camera3': 'yolov5l.pt',
  'model_size_camera4': 'yolov5s.pt',
  'model_size_camera5': 'yolov5m.pt',
  'resolution_camera1': '1280',
  'resolution_camera2': '320',
  'resolution_camera3': '320',
  'resolution_camera4': '1280',
  'resolution_camera5': '320',
})

[2024-01-23 23:38:20,159][0][INFO][generic_smbo.py:295] Iter 8, objectives: [inf, inf].
[2024-01-23 23:38:51,274][0][ERROR][generic_smbo.py:275] Exception in objective function:
Traceback (most recent call last):
  File "/data1/xiayuyang/anaconda3/envs/carla/lib/python3.8/site-packages/openbox/utils/limit.py", line 62, in run_without_time_limit
    ret = obj_func(*obj_args, **obj_kwargs)
  File "/data1/xiayuyang/online_mcmt/detector/yolov5/bo.py", line 80, in multi_camera_matching
    accuracy, processing_time = profile(
  File "/data1/xiayuyang/online_mcmt/detector/yolov5/my_mtmc.py", line 910, in profile
    gt_detect, gt_dict, total_detect_time, total_extract_time, total_sct_time, total_pp_time, total_match_time=run_mtmc(cams_dir=cams_dir_, weights=weights_, imgsz=imgsz_, cams_ratio=cams_ratio_, lazy_threshold=lazy_threshold_)
  File "/data1/xiayuyang/online_mcmt/detector/yolov5/my_mtmc.py", line 792, in run_mtmc
    g_tid += 1
UnboundLocalError: local variable 'g_tid' referenced before assignment

config: Configuration(values={
  'fps_camera1': '4',
  'fps_camera2': '10',
  'fps_camera3': '4',
  'fps_camera4': '1',
  'fps_camera5': '4',
  'lazy_threshold': 0.74,
  'model_size_camera1': 'yolov5s.pt',
  'model_size_camera2': 'yolov5l.pt',
  'model_size_camera3': 'yolov5s.pt',
  'model_size_camera4': 'yolov5l.pt',
  'model_size_camera5': 'yolov5m.pt',
  'resolution_camera1': '320',
  'resolution_camera2': '640',
  'resolution_camera3': '1280',
  'resolution_camera4': '1280',
  'resolution_camera5': '320',
})

[2024-01-23 23:38:51,275][0][INFO][generic_smbo.py:295] Iter 9, objectives: [inf, inf].
[2024-01-23 23:38:51,279][0][WARNING][generic_advisor.py:375] No enough successful initial trials! Sample random configuration.
[2024-01-23 23:39:16,663][0][ERROR][generic_smbo.py:275] Exception in objective function:
Traceback (most recent call last):
  File "/data1/xiayuyang/anaconda3/envs/carla/lib/python3.8/site-packages/openbox/utils/limit.py", line 62, in run_without_time_limit
    ret = obj_func(*obj_args, **obj_kwargs)
  File "/data1/xiayuyang/online_mcmt/detector/yolov5/bo.py", line 80, in multi_camera_matching
    accuracy, processing_time = profile(
  File "/data1/xiayuyang/online_mcmt/detector/yolov5/my_mtmc.py", line 910, in profile
    gt_detect, gt_dict, total_detect_time, total_extract_time, total_sct_time, total_pp_time, total_match_time=run_mtmc(cams_dir=cams_dir_, weights=weights_, imgsz=imgsz_, cams_ratio=cams_ratio_, lazy_threshold=lazy_threshold_)
  File "/data1/xiayuyang/online_mcmt/detector/yolov5/my_mtmc.py", line 792, in run_mtmc
    g_tid += 1
UnboundLocalError: local variable 'g_tid' referenced before assignment

config: Configuration(values={
  'fps_camera1': '4',
  'fps_camera2': '2',
  'fps_camera3': '10',
  'fps_camera4': '10',
  'fps_camera5': '4',
  'lazy_threshold': 0.88,
  'model_size_camera1': 'yolov5s.pt',
  'model_size_camera2': 'yolov5s.pt',
  'model_size_camera3': 'yolov5m.pt',
  'model_size_camera4': 'yolov5m.pt',
  'model_size_camera5': 'yolov5l.pt',
  'resolution_camera1': '640',
  'resolution_camera2': '1280',
  'resolution_camera3': '1280',
  'resolution_camera4': '320',
  'resolution_camera5': '1280',
})

[2024-01-23 23:39:16,664][0][INFO][generic_smbo.py:295] Iter 10, objectives: [inf, inf].
[2024-01-23 23:39:16,667][0][WARNING][generic_advisor.py:375] No enough successful initial trials! Sample random configuration.
[2024-01-23 23:39:42,607][0][ERROR][generic_smbo.py:275] Exception in objective function:
Traceback (most recent call last):
  File "/data1/xiayuyang/anaconda3/envs/carla/lib/python3.8/site-packages/openbox/utils/limit.py", line 62, in run_without_time_limit
    ret = obj_func(*obj_args, **obj_kwargs)
  File "/data1/xiayuyang/online_mcmt/detector/yolov5/bo.py", line 80, in multi_camera_matching
    accuracy, processing_time = profile(
  File "/data1/xiayuyang/online_mcmt/detector/yolov5/my_mtmc.py", line 910, in profile
    gt_detect, gt_dict, total_detect_time, total_extract_time, total_sct_time, total_pp_time, total_match_time=run_mtmc(cams_dir=cams_dir_, weights=weights_, imgsz=imgsz_, cams_ratio=cams_ratio_, lazy_threshold=lazy_threshold_)
  File "/data1/xiayuyang/online_mcmt/detector/yolov5/my_mtmc.py", line 792, in run_mtmc
    g_tid += 1
UnboundLocalError: local variable 'g_tid' referenced before assignment

config: Configuration(values={
  'fps_camera1': '1',
  'fps_camera2': '2',
  'fps_camera3': '1',
  'fps_camera4': '2',
  'fps_camera5': '4',
  'lazy_threshold': 0.86,
  'model_size_camera1': 'yolov5s.pt',
  'model_size_camera2': 'yolov5l.pt',
  'model_size_camera3': 'yolov5m.pt',
  'model_size_camera4': 'yolov5l.pt',
  'model_size_camera5': 'yolov5s.pt',
  'resolution_camera1': '640',
  'resolution_camera2': '320',
  'resolution_camera3': '640',
  'resolution_camera4': '640',
  'resolution_camera5': '640',
})

[2024-01-23 23:39:42,608][0][INFO][generic_smbo.py:295] Iter 11, objectives: [inf, inf].
[2024-01-23 23:39:42,610][0][WARNING][generic_advisor.py:375] No enough successful initial trials! Sample random configuration.
[2024-01-23 23:40:19,762][0][ERROR][generic_smbo.py:275] Exception in objective function:
Traceback (most recent call last):
  File "/data1/xiayuyang/anaconda3/envs/carla/lib/python3.8/site-packages/openbox/utils/limit.py", line 62, in run_without_time_limit
    ret = obj_func(*obj_args, **obj_kwargs)
  File "/data1/xiayuyang/online_mcmt/detector/yolov5/bo.py", line 80, in multi_camera_matching
    accuracy, processing_time = profile(
  File "/data1/xiayuyang/online_mcmt/detector/yolov5/my_mtmc.py", line 910, in profile
    gt_detect, gt_dict, total_detect_time, total_extract_time, total_sct_time, total_pp_time, total_match_time=run_mtmc(cams_dir=cams_dir_, weights=weights_, imgsz=imgsz_, cams_ratio=cams_ratio_, lazy_threshold=lazy_threshold_)
  File "/data1/xiayuyang/online_mcmt/detector/yolov5/my_mtmc.py", line 792, in run_mtmc
    g_tid += 1
UnboundLocalError: local variable 'g_tid' referenced before assignment

config: Configuration(values={
  'fps_camera1': '4',
  'fps_camera2': '2',
  'fps_camera3': '1',
  'fps_camera4': '4',
  'fps_camera5': '10',
  'lazy_threshold': 0.82,
  'model_size_camera1': 'yolov5l.pt',
  'model_size_camera2': 'yolov5s.pt',
  'model_size_camera3': 'yolov5s.pt',
  'model_size_camera4': 'yolov5l.pt',
  'model_size_camera5': 'yolov5l.pt',
  'resolution_camera1': '1280',
  'resolution_camera2': '640',
  'resolution_camera3': '1280',
  'resolution_camera4': '640',
  'resolution_camera5': '640',
})

[2024-01-23 23:40:19,763][0][INFO][generic_smbo.py:295] Iter 12, objectives: [inf, inf].
[2024-01-23 23:40:19,765][0][WARNING][generic_advisor.py:375] No enough successful initial trials! Sample random configuration.
[2024-01-23 23:40:53,354][0][ERROR][generic_smbo.py:275] Exception in objective function:
Traceback (most recent call last):
  File "/data1/xiayuyang/anaconda3/envs/carla/lib/python3.8/site-packages/openbox/utils/limit.py", line 62, in run_without_time_limit
    ret = obj_func(*obj_args, **obj_kwargs)
  File "/data1/xiayuyang/online_mcmt/detector/yolov5/bo.py", line 80, in multi_camera_matching
    accuracy, processing_time = profile(
  File "/data1/xiayuyang/online_mcmt/detector/yolov5/my_mtmc.py", line 910, in profile
    gt_detect, gt_dict, total_detect_time, total_extract_time, total_sct_time, total_pp_time, total_match_time=run_mtmc(cams_dir=cams_dir_, weights=weights_, imgsz=imgsz_, cams_ratio=cams_ratio_, lazy_threshold=lazy_threshold_)
  File "/data1/xiayuyang/online_mcmt/detector/yolov5/my_mtmc.py", line 792, in run_mtmc
    g_tid += 1
UnboundLocalError: local variable 'g_tid' referenced before assignment

config: Configuration(values={
  'fps_camera1': '10',
  'fps_camera2': '1',
  'fps_camera3': '2',
  'fps_camera4': '10',
  'fps_camera5': '2',
  'lazy_threshold': 0.82,
  'model_size_camera1': 'yolov5s.pt',
  'model_size_camera2': 'yolov5m.pt',
  'model_size_camera3': 'yolov5l.pt',
  'model_size_camera4': 'yolov5m.pt',
  'model_size_camera5': 'yolov5m.pt',
  'resolution_camera1': '1280',
  'resolution_camera2': '1280',
  'resolution_camera3': '640',
  'resolution_camera4': '640',
  'resolution_camera5': '1280',
})

[2024-01-23 23:40:53,355][0][INFO][generic_smbo.py:295] Iter 13, objectives: [inf, inf].
[2024-01-23 23:40:53,357][0][WARNING][generic_advisor.py:375] No enough successful initial trials! Sample random configuration.
[2024-01-23 23:41:19,392][0][ERROR][generic_smbo.py:275] Exception in objective function:
Traceback (most recent call last):
  File "/data1/xiayuyang/anaconda3/envs/carla/lib/python3.8/site-packages/openbox/utils/limit.py", line 62, in run_without_time_limit
    ret = obj_func(*obj_args, **obj_kwargs)
  File "/data1/xiayuyang/online_mcmt/detector/yolov5/bo.py", line 80, in multi_camera_matching
    accuracy, processing_time = profile(
  File "/data1/xiayuyang/online_mcmt/detector/yolov5/my_mtmc.py", line 910, in profile
    gt_detect, gt_dict, total_detect_time, total_extract_time, total_sct_time, total_pp_time, total_match_time=run_mtmc(cams_dir=cams_dir_, weights=weights_, imgsz=imgsz_, cams_ratio=cams_ratio_, lazy_threshold=lazy_threshold_)
  File "/data1/xiayuyang/online_mcmt/detector/yolov5/my_mtmc.py", line 792, in run_mtmc
    g_tid += 1
UnboundLocalError: local variable 'g_tid' referenced before assignment

config: Configuration(values={
  'fps_camera1': '2',
  'fps_camera2': '4',
  'fps_camera3': '2',
  'fps_camera4': '1',
  'fps_camera5': '1',
  'lazy_threshold': 0.62,
  'model_size_camera1': 'yolov5l.pt',
  'model_size_camera2': 'yolov5s.pt',
  'model_size_camera3': 'yolov5l.pt',
  'model_size_camera4': 'yolov5m.pt',
  'model_size_camera5': 'yolov5l.pt',
  'resolution_camera1': '320',
  'resolution_camera2': '320',
  'resolution_camera3': '320',
  'resolution_camera4': '320',
  'resolution_camera5': '640',
})

[2024-01-23 23:41:19,394][0][INFO][generic_smbo.py:295] Iter 14, objectives: [inf, inf].
[2024-01-23 23:41:19,397][0][WARNING][generic_advisor.py:375] No enough successful initial trials! Sample random configuration.
[2024-01-23 23:41:54,950][0][ERROR][generic_smbo.py:275] Exception in objective function:
Traceback (most recent call last):
  File "/data1/xiayuyang/anaconda3/envs/carla/lib/python3.8/site-packages/openbox/utils/limit.py", line 62, in run_without_time_limit
    ret = obj_func(*obj_args, **obj_kwargs)
  File "/data1/xiayuyang/online_mcmt/detector/yolov5/bo.py", line 80, in multi_camera_matching
    accuracy, processing_time = profile(
  File "/data1/xiayuyang/online_mcmt/detector/yolov5/my_mtmc.py", line 910, in profile
    gt_detect, gt_dict, total_detect_time, total_extract_time, total_sct_time, total_pp_time, total_match_time=run_mtmc(cams_dir=cams_dir_, weights=weights_, imgsz=imgsz_, cams_ratio=cams_ratio_, lazy_threshold=lazy_threshold_)
  File "/data1/xiayuyang/online_mcmt/detector/yolov5/my_mtmc.py", line 792, in run_mtmc
    g_tid += 1
UnboundLocalError: local variable 'g_tid' referenced before assignment

config: Configuration(values={
  'fps_camera1': '2',
  'fps_camera2': '4',
  'fps_camera3': '1',
  'fps_camera4': '10',
  'fps_camera5': '2',
  'lazy_threshold': 0.64,
  'model_size_camera1': 'yolov5l.pt',
  'model_size_camera2': 'yolov5m.pt',
  'model_size_camera3': 'yolov5l.pt',
  'model_size_camera4': 'yolov5l.pt',
  'model_size_camera5': 'yolov5m.pt',
  'resolution_camera1': '640',
  'resolution_camera2': '640',
  'resolution_camera3': '640',
  'resolution_camera4': '640',
  'resolution_camera5': '1280',
})

[2024-01-23 23:41:54,952][0][INFO][generic_smbo.py:295] Iter 15, objectives: [inf, inf].
[2024-01-23 23:41:54,954][0][WARNING][generic_advisor.py:375] No enough successful initial trials! Sample random configuration.
[2024-01-23 23:42:21,965][0][ERROR][generic_smbo.py:275] Exception in objective function:
Traceback (most recent call last):
  File "/data1/xiayuyang/anaconda3/envs/carla/lib/python3.8/site-packages/openbox/utils/limit.py", line 62, in run_without_time_limit
    ret = obj_func(*obj_args, **obj_kwargs)
  File "/data1/xiayuyang/online_mcmt/detector/yolov5/bo.py", line 80, in multi_camera_matching
    accuracy, processing_time = profile(
  File "/data1/xiayuyang/online_mcmt/detector/yolov5/my_mtmc.py", line 910, in profile
    gt_detect, gt_dict, total_detect_time, total_extract_time, total_sct_time, total_pp_time, total_match_time=run_mtmc(cams_dir=cams_dir_, weights=weights_, imgsz=imgsz_, cams_ratio=cams_ratio_, lazy_threshold=lazy_threshold_)
  File "/data1/xiayuyang/online_mcmt/detector/yolov5/my_mtmc.py", line 792, in run_mtmc
    g_tid += 1
UnboundLocalError: local variable 'g_tid' referenced before assignment

config: Configuration(values={
  'fps_camera1': '4',
  'fps_camera2': '4',
  'fps_camera3': '1',
  'fps_camera4': '2',
  'fps_camera5': '2',
  'lazy_threshold': 0.84,
  'model_size_camera1': 'yolov5l.pt',
  'model_size_camera2': 'yolov5m.pt',
  'model_size_camera3': 'yolov5m.pt',
  'model_size_camera4': 'yolov5l.pt',
  'model_size_camera5': 'yolov5l.pt',
  'resolution_camera1': '320',
  'resolution_camera2': '320',
  'resolution_camera3': '640',
  'resolution_camera4': '640',
  'resolution_camera5': '1280',
})

[2024-01-23 23:42:21,967][0][INFO][generic_smbo.py:295] Iter 16, objectives: [inf, inf].
[2024-01-23 23:42:21,969][0][WARNING][generic_advisor.py:375] No enough successful initial trials! Sample random configuration.
[2024-01-23 23:42:49,199][0][ERROR][generic_smbo.py:275] Exception in objective function:
Traceback (most recent call last):
  File "/data1/xiayuyang/anaconda3/envs/carla/lib/python3.8/site-packages/openbox/utils/limit.py", line 62, in run_without_time_limit
    ret = obj_func(*obj_args, **obj_kwargs)
  File "/data1/xiayuyang/online_mcmt/detector/yolov5/bo.py", line 80, in multi_camera_matching
    accuracy, processing_time = profile(
  File "/data1/xiayuyang/online_mcmt/detector/yolov5/my_mtmc.py", line 910, in profile
    gt_detect, gt_dict, total_detect_time, total_extract_time, total_sct_time, total_pp_time, total_match_time=run_mtmc(cams_dir=cams_dir_, weights=weights_, imgsz=imgsz_, cams_ratio=cams_ratio_, lazy_threshold=lazy_threshold_)
  File "/data1/xiayuyang/online_mcmt/detector/yolov5/my_mtmc.py", line 792, in run_mtmc
    g_tid += 1
UnboundLocalError: local variable 'g_tid' referenced before assignment

config: Configuration(values={
  'fps_camera1': '10',
  'fps_camera2': '1',
  'fps_camera3': '2',
  'fps_camera4': '1',
  'fps_camera5': '4',
  'lazy_threshold': 0.7,
  'model_size_camera1': 'yolov5l.pt',
  'model_size_camera2': 'yolov5l.pt',
  'model_size_camera3': 'yolov5l.pt',
  'model_size_camera4': 'yolov5s.pt',
  'model_size_camera5': 'yolov5l.pt',
  'resolution_camera1': '640',
  'resolution_camera2': '1280',
  'resolution_camera3': '640',
  'resolution_camera4': '320',
  'resolution_camera5': '320',
})

[2024-01-23 23:42:49,200][0][INFO][generic_smbo.py:295] Iter 17, objectives: [inf, inf].
[2024-01-23 23:42:49,202][0][WARNING][generic_advisor.py:375] No enough successful initial trials! Sample random configuration.
[2024-01-23 23:43:17,173][0][ERROR][generic_smbo.py:275] Exception in objective function:
Traceback (most recent call last):
  File "/data1/xiayuyang/anaconda3/envs/carla/lib/python3.8/site-packages/openbox/utils/limit.py", line 62, in run_without_time_limit
    ret = obj_func(*obj_args, **obj_kwargs)
  File "/data1/xiayuyang/online_mcmt/detector/yolov5/bo.py", line 80, in multi_camera_matching
    accuracy, processing_time = profile(
  File "/data1/xiayuyang/online_mcmt/detector/yolov5/my_mtmc.py", line 910, in profile
    gt_detect, gt_dict, total_detect_time, total_extract_time, total_sct_time, total_pp_time, total_match_time=run_mtmc(cams_dir=cams_dir_, weights=weights_, imgsz=imgsz_, cams_ratio=cams_ratio_, lazy_threshold=lazy_threshold_)
  File "/data1/xiayuyang/online_mcmt/detector/yolov5/my_mtmc.py", line 792, in run_mtmc
    g_tid += 1
UnboundLocalError: local variable 'g_tid' referenced before assignment

config: Configuration(values={
  'fps_camera1': '1',
  'fps_camera2': '10',
  'fps_camera3': '4',
  'fps_camera4': '2',
  'fps_camera5': '1',
  'lazy_threshold': 0.72,
  'model_size_camera1': 'yolov5l.pt',
  'model_size_camera2': 'yolov5s.pt',
  'model_size_camera3': 'yolov5s.pt',
  'model_size_camera4': 'yolov5l.pt',
  'model_size_camera5': 'yolov5s.pt',
  'resolution_camera1': '640',
  'resolution_camera2': '640',
  'resolution_camera3': '1280',
  'resolution_camera4': '320',
  'resolution_camera5': '320',
})

[2024-01-23 23:43:17,174][0][INFO][generic_smbo.py:295] Iter 18, objectives: [inf, inf].
[2024-01-23 23:43:17,176][0][WARNING][generic_advisor.py:375] No enough successful initial trials! Sample random configuration.
[2024-01-23 23:43:50,636][0][ERROR][generic_smbo.py:275] Exception in objective function:
Traceback (most recent call last):
  File "/data1/xiayuyang/anaconda3/envs/carla/lib/python3.8/site-packages/openbox/utils/limit.py", line 62, in run_without_time_limit
    ret = obj_func(*obj_args, **obj_kwargs)
  File "/data1/xiayuyang/online_mcmt/detector/yolov5/bo.py", line 80, in multi_camera_matching
    accuracy, processing_time = profile(
  File "/data1/xiayuyang/online_mcmt/detector/yolov5/my_mtmc.py", line 910, in profile
    gt_detect, gt_dict, total_detect_time, total_extract_time, total_sct_time, total_pp_time, total_match_time=run_mtmc(cams_dir=cams_dir_, weights=weights_, imgsz=imgsz_, cams_ratio=cams_ratio_, lazy_threshold=lazy_threshold_)
  File "/data1/xiayuyang/online_mcmt/detector/yolov5/my_mtmc.py", line 792, in run_mtmc
    g_tid += 1
UnboundLocalError: local variable 'g_tid' referenced before assignment

config: Configuration(values={
  'fps_camera1': '4',
  'fps_camera2': '10',
  'fps_camera3': '4',
  'fps_camera4': '1',
  'fps_camera5': '4',
  'lazy_threshold': 0.6,
  'model_size_camera1': 'yolov5m.pt',
  'model_size_camera2': 'yolov5l.pt',
  'model_size_camera3': 'yolov5m.pt',
  'model_size_camera4': 'yolov5s.pt',
  'model_size_camera5': 'yolov5l.pt',
  'resolution_camera1': '640',
  'resolution_camera2': '320',
  'resolution_camera3': '1280',
  'resolution_camera4': '1280',
  'resolution_camera5': '1280',
})

[2024-01-23 23:43:50,637][0][INFO][generic_smbo.py:295] Iter 19, objectives: [inf, inf].
[2024-01-23 23:43:50,639][0][WARNING][generic_advisor.py:375] No enough successful initial trials! Sample random configuration.
[2024-01-23 23:44:12,982][0][ERROR][generic_smbo.py:275] Exception in objective function:
Traceback (most recent call last):
  File "/data1/xiayuyang/anaconda3/envs/carla/lib/python3.8/site-packages/openbox/utils/limit.py", line 62, in run_without_time_limit
    ret = obj_func(*obj_args, **obj_kwargs)
  File "/data1/xiayuyang/online_mcmt/detector/yolov5/bo.py", line 80, in multi_camera_matching
    accuracy, processing_time = profile(
  File "/data1/xiayuyang/online_mcmt/detector/yolov5/my_mtmc.py", line 910, in profile
    gt_detect, gt_dict, total_detect_time, total_extract_time, total_sct_time, total_pp_time, total_match_time=run_mtmc(cams_dir=cams_dir_, weights=weights_, imgsz=imgsz_, cams_ratio=cams_ratio_, lazy_threshold=lazy_threshold_)
  File "/data1/xiayuyang/online_mcmt/detector/yolov5/my_mtmc.py", line 792, in run_mtmc
    g_tid += 1
UnboundLocalError: local variable 'g_tid' referenced before assignment

config: Configuration(values={
  'fps_camera1': '1',
  'fps_camera2': '4',
  'fps_camera3': '2',
  'fps_camera4': '1',
  'fps_camera5': '2',
  'lazy_threshold': 0.8,
  'model_size_camera1': 'yolov5s.pt',
  'model_size_camera2': 'yolov5m.pt',
  'model_size_camera3': 'yolov5m.pt',
  'model_size_camera4': 'yolov5m.pt',
  'model_size_camera5': 'yolov5m.pt',
  'resolution_camera1': '320',
  'resolution_camera2': '320',
  'resolution_camera3': '640',
  'resolution_camera4': '320',
  'resolution_camera5': '320',
})

[2024-01-23 23:44:12,984][0][INFO][generic_smbo.py:295] Iter 20, objectives: [inf, inf].
[2024-01-23 23:44:12,986][0][WARNING][generic_advisor.py:375] No enough successful initial trials! Sample random configuration.
[2024-01-23 23:44:37,532][0][ERROR][generic_smbo.py:275] Exception in objective function:
Traceback (most recent call last):
  File "/data1/xiayuyang/anaconda3/envs/carla/lib/python3.8/site-packages/openbox/utils/limit.py", line 62, in run_without_time_limit
    ret = obj_func(*obj_args, **obj_kwargs)
  File "/data1/xiayuyang/online_mcmt/detector/yolov5/bo.py", line 80, in multi_camera_matching
    accuracy, processing_time = profile(
  File "/data1/xiayuyang/online_mcmt/detector/yolov5/my_mtmc.py", line 910, in profile
    gt_detect, gt_dict, total_detect_time, total_extract_time, total_sct_time, total_pp_time, total_match_time=run_mtmc(cams_dir=cams_dir_, weights=weights_, imgsz=imgsz_, cams_ratio=cams_ratio_, lazy_threshold=lazy_threshold_)
  File "/data1/xiayuyang/online_mcmt/detector/yolov5/my_mtmc.py", line 792, in run_mtmc
    g_tid += 1
UnboundLocalError: local variable 'g_tid' referenced before assignment

config: Configuration(values={
  'fps_camera1': '2',
  'fps_camera2': '1',
  'fps_camera3': '4',
  'fps_camera4': '1',
  'fps_camera5': '1',
  'lazy_threshold': 0.74,
  'model_size_camera1': 'yolov5s.pt',
  'model_size_camera2': 'yolov5s.pt',
  'model_size_camera3': 'yolov5l.pt',
  'model_size_camera4': 'yolov5m.pt',
  'model_size_camera5': 'yolov5m.pt',
  'resolution_camera1': '320',
  'resolution_camera2': '320',
  'resolution_camera3': '320',
  'resolution_camera4': '320',
  'resolution_camera5': '640',
})

[2024-01-23 23:44:37,533][0][INFO][generic_smbo.py:295] Iter 21, objectives: [inf, inf].
[2024-01-23 23:44:37,534][0][WARNING][generic_advisor.py:375] No enough successful initial trials! Sample random configuration.
[2024-01-23 23:45:03,320][0][ERROR][generic_smbo.py:275] Exception in objective function:
Traceback (most recent call last):
  File "/data1/xiayuyang/anaconda3/envs/carla/lib/python3.8/site-packages/openbox/utils/limit.py", line 62, in run_without_time_limit
    ret = obj_func(*obj_args, **obj_kwargs)
  File "/data1/xiayuyang/online_mcmt/detector/yolov5/bo.py", line 80, in multi_camera_matching
    accuracy, processing_time = profile(
  File "/data1/xiayuyang/online_mcmt/detector/yolov5/my_mtmc.py", line 910, in profile
    gt_detect, gt_dict, total_detect_time, total_extract_time, total_sct_time, total_pp_time, total_match_time=run_mtmc(cams_dir=cams_dir_, weights=weights_, imgsz=imgsz_, cams_ratio=cams_ratio_, lazy_threshold=lazy_threshold_)
  File "/data1/xiayuyang/online_mcmt/detector/yolov5/my_mtmc.py", line 792, in run_mtmc
    g_tid += 1
UnboundLocalError: local variable 'g_tid' referenced before assignment

config: Configuration(values={
  'fps_camera1': '1',
  'fps_camera2': '1',
  'fps_camera3': '2',
  'fps_camera4': '4',
  'fps_camera5': '4',
  'lazy_threshold': 0.6799999999999999,
  'model_size_camera1': 'yolov5m.pt',
  'model_size_camera2': 'yolov5m.pt',
  'model_size_camera3': 'yolov5s.pt',
  'model_size_camera4': 'yolov5s.pt',
  'model_size_camera5': 'yolov5l.pt',
  'resolution_camera1': '320',
  'resolution_camera2': '640',
  'resolution_camera3': '1280',
  'resolution_camera4': '1280',
  'resolution_camera5': '640',
})

[2024-01-23 23:45:03,321][0][INFO][generic_smbo.py:295] Iter 22, objectives: [inf, inf].
[2024-01-23 23:45:03,323][0][WARNING][generic_advisor.py:375] No enough successful initial trials! Sample random configuration.
[2024-01-23 23:45:34,162][0][ERROR][generic_smbo.py:275] Exception in objective function:
Traceback (most recent call last):
  File "/data1/xiayuyang/anaconda3/envs/carla/lib/python3.8/site-packages/openbox/utils/limit.py", line 62, in run_without_time_limit
    ret = obj_func(*obj_args, **obj_kwargs)
  File "/data1/xiayuyang/online_mcmt/detector/yolov5/bo.py", line 80, in multi_camera_matching
    accuracy, processing_time = profile(
  File "/data1/xiayuyang/online_mcmt/detector/yolov5/my_mtmc.py", line 910, in profile
    gt_detect, gt_dict, total_detect_time, total_extract_time, total_sct_time, total_pp_time, total_match_time=run_mtmc(cams_dir=cams_dir_, weights=weights_, imgsz=imgsz_, cams_ratio=cams_ratio_, lazy_threshold=lazy_threshold_)
  File "/data1/xiayuyang/online_mcmt/detector/yolov5/my_mtmc.py", line 792, in run_mtmc
    g_tid += 1
UnboundLocalError: local variable 'g_tid' referenced before assignment

config: Configuration(values={
  'fps_camera1': '4',
  'fps_camera2': '2',
  'fps_camera3': '1',
  'fps_camera4': '2',
  'fps_camera5': '1',
  'lazy_threshold': 0.6,
  'model_size_camera1': 'yolov5s.pt',
  'model_size_camera2': 'yolov5m.pt',
  'model_size_camera3': 'yolov5s.pt',
  'model_size_camera4': 'yolov5m.pt',
  'model_size_camera5': 'yolov5s.pt',
  'resolution_camera1': '640',
  'resolution_camera2': '640',
  'resolution_camera3': '1280',
  'resolution_camera4': '1280',
  'resolution_camera5': '320',
})

[2024-01-23 23:45:34,164][0][INFO][generic_smbo.py:295] Iter 23, objectives: [inf, inf].
[2024-01-23 23:45:34,167][0][WARNING][generic_advisor.py:375] No enough successful initial trials! Sample random configuration.
[2024-01-23 23:45:52,896][0][ERROR][generic_smbo.py:275] Exception in objective function:
Traceback (most recent call last):
  File "/data1/xiayuyang/anaconda3/envs/carla/lib/python3.8/site-packages/openbox/utils/limit.py", line 62, in run_without_time_limit
    ret = obj_func(*obj_args, **obj_kwargs)
  File "/data1/xiayuyang/online_mcmt/detector/yolov5/bo.py", line 80, in multi_camera_matching
    accuracy, processing_time = profile(
  File "/data1/xiayuyang/online_mcmt/detector/yolov5/my_mtmc.py", line 910, in profile
    gt_detect, gt_dict, total_detect_time, total_extract_time, total_sct_time, total_pp_time, total_match_time=run_mtmc(cams_dir=cams_dir_, weights=weights_, imgsz=imgsz_, cams_ratio=cams_ratio_, lazy_threshold=lazy_threshold_)
  File "/data1/xiayuyang/online_mcmt/detector/yolov5/my_mtmc.py", line 792, in run_mtmc
    g_tid += 1
UnboundLocalError: local variable 'g_tid' referenced before assignment

config: Configuration(values={
  'fps_camera1': '2',
  'fps_camera2': '10',
  'fps_camera3': '10',
  'fps_camera4': '2',
  'fps_camera5': '4',
  'lazy_threshold': 0.78,
  'model_size_camera1': 'yolov5m.pt',
  'model_size_camera2': 'yolov5m.pt',
  'model_size_camera3': 'yolov5m.pt',
  'model_size_camera4': 'yolov5l.pt',
  'model_size_camera5': 'yolov5m.pt',
  'resolution_camera1': '320',
  'resolution_camera2': '1280',
  'resolution_camera3': '1280',
  'resolution_camera4': '320',
  'resolution_camera5': '320',
})

[2024-01-23 23:45:52,898][0][INFO][generic_smbo.py:295] Iter 24, objectives: [inf, inf].
[2024-01-23 23:45:52,900][0][WARNING][generic_advisor.py:375] No enough successful initial trials! Sample random configuration.
[2024-01-23 23:46:15,947][0][ERROR][generic_smbo.py:275] Exception in objective function:
Traceback (most recent call last):
  File "/data1/xiayuyang/anaconda3/envs/carla/lib/python3.8/site-packages/openbox/utils/limit.py", line 62, in run_without_time_limit
    ret = obj_func(*obj_args, **obj_kwargs)
  File "/data1/xiayuyang/online_mcmt/detector/yolov5/bo.py", line 80, in multi_camera_matching
    accuracy, processing_time = profile(
  File "/data1/xiayuyang/online_mcmt/detector/yolov5/my_mtmc.py", line 910, in profile
    gt_detect, gt_dict, total_detect_time, total_extract_time, total_sct_time, total_pp_time, total_match_time=run_mtmc(cams_dir=cams_dir_, weights=weights_, imgsz=imgsz_, cams_ratio=cams_ratio_, lazy_threshold=lazy_threshold_)
  File "/data1/xiayuyang/online_mcmt/detector/yolov5/my_mtmc.py", line 792, in run_mtmc
    g_tid += 1
UnboundLocalError: local variable 'g_tid' referenced before assignment

config: Configuration(values={
  'fps_camera1': '10',
  'fps_camera2': '4',
  'fps_camera3': '2',
  'fps_camera4': '2',
  'fps_camera5': '4',
  'lazy_threshold': 0.88,
  'model_size_camera1': 'yolov5s.pt',
  'model_size_camera2': 'yolov5l.pt',
  'model_size_camera3': 'yolov5s.pt',
  'model_size_camera4': 'yolov5l.pt',
  'model_size_camera5': 'yolov5s.pt',
  'resolution_camera1': '1280',
  'resolution_camera2': '320',
  'resolution_camera3': '640',
  'resolution_camera4': '640',
  'resolution_camera5': '1280',
})

[2024-01-23 23:46:15,948][0][INFO][generic_smbo.py:295] Iter 25, objectives: [inf, inf].
[2024-01-23 23:46:15,950][0][WARNING][generic_advisor.py:375] No enough successful initial trials! Sample random configuration.
[2024-01-23 23:46:43,777][0][ERROR][generic_smbo.py:275] Exception in objective function:
Traceback (most recent call last):
  File "/data1/xiayuyang/anaconda3/envs/carla/lib/python3.8/site-packages/openbox/utils/limit.py", line 62, in run_without_time_limit
    ret = obj_func(*obj_args, **obj_kwargs)
  File "/data1/xiayuyang/online_mcmt/detector/yolov5/bo.py", line 80, in multi_camera_matching
    accuracy, processing_time = profile(
  File "/data1/xiayuyang/online_mcmt/detector/yolov5/my_mtmc.py", line 910, in profile
    gt_detect, gt_dict, total_detect_time, total_extract_time, total_sct_time, total_pp_time, total_match_time=run_mtmc(cams_dir=cams_dir_, weights=weights_, imgsz=imgsz_, cams_ratio=cams_ratio_, lazy_threshold=lazy_threshold_)
  File "/data1/xiayuyang/online_mcmt/detector/yolov5/my_mtmc.py", line 792, in run_mtmc
    g_tid += 1
UnboundLocalError: local variable 'g_tid' referenced before assignment

config: Configuration(values={
  'fps_camera1': '1',
  'fps_camera2': '4',
  'fps_camera3': '2',
  'fps_camera4': '1',
  'fps_camera5': '10',
  'lazy_threshold': 0.6,
  'model_size_camera1': 'yolov5l.pt',
  'model_size_camera2': 'yolov5m.pt',
  'model_size_camera3': 'yolov5l.pt',
  'model_size_camera4': 'yolov5s.pt',
  'model_size_camera5': 'yolov5m.pt',
  'resolution_camera1': '320',
  'resolution_camera2': '320',
  'resolution_camera3': '1280',
  'resolution_camera4': '640',
  'resolution_camera5': '1280',
})

[2024-01-23 23:46:43,779][0][INFO][generic_smbo.py:295] Iter 26, objectives: [inf, inf].
[2024-01-23 23:46:43,781][0][WARNING][generic_advisor.py:375] No enough successful initial trials! Sample random configuration.
[2024-01-23 23:47:14,449][0][ERROR][generic_smbo.py:275] Exception in objective function:
Traceback (most recent call last):
  File "/data1/xiayuyang/anaconda3/envs/carla/lib/python3.8/site-packages/openbox/utils/limit.py", line 62, in run_without_time_limit
    ret = obj_func(*obj_args, **obj_kwargs)
  File "/data1/xiayuyang/online_mcmt/detector/yolov5/bo.py", line 80, in multi_camera_matching
    accuracy, processing_time = profile(
  File "/data1/xiayuyang/online_mcmt/detector/yolov5/my_mtmc.py", line 910, in profile
    gt_detect, gt_dict, total_detect_time, total_extract_time, total_sct_time, total_pp_time, total_match_time=run_mtmc(cams_dir=cams_dir_, weights=weights_, imgsz=imgsz_, cams_ratio=cams_ratio_, lazy_threshold=lazy_threshold_)
  File "/data1/xiayuyang/online_mcmt/detector/yolov5/my_mtmc.py", line 792, in run_mtmc
    g_tid += 1
UnboundLocalError: local variable 'g_tid' referenced before assignment

config: Configuration(values={
  'fps_camera1': '10',
  'fps_camera2': '2',
  'fps_camera3': '2',
  'fps_camera4': '2',
  'fps_camera5': '10',
  'lazy_threshold': 0.64,
  'model_size_camera1': 'yolov5s.pt',
  'model_size_camera2': 'yolov5m.pt',
  'model_size_camera3': 'yolov5m.pt',
  'model_size_camera4': 'yolov5s.pt',
  'model_size_camera5': 'yolov5m.pt',
  'resolution_camera1': '320',
  'resolution_camera2': '640',
  'resolution_camera3': '1280',
  'resolution_camera4': '640',
  'resolution_camera5': '1280',
})

[2024-01-23 23:47:14,449][0][INFO][generic_smbo.py:295] Iter 27, objectives: [inf, inf].
[2024-01-23 23:47:14,451][0][WARNING][generic_advisor.py:375] No enough successful initial trials! Sample random configuration.
[2024-01-23 23:47:39,881][0][ERROR][generic_smbo.py:275] Exception in objective function:
Traceback (most recent call last):
  File "/data1/xiayuyang/anaconda3/envs/carla/lib/python3.8/site-packages/openbox/utils/limit.py", line 62, in run_without_time_limit
    ret = obj_func(*obj_args, **obj_kwargs)
  File "/data1/xiayuyang/online_mcmt/detector/yolov5/bo.py", line 80, in multi_camera_matching
    accuracy, processing_time = profile(
  File "/data1/xiayuyang/online_mcmt/detector/yolov5/my_mtmc.py", line 910, in profile
    gt_detect, gt_dict, total_detect_time, total_extract_time, total_sct_time, total_pp_time, total_match_time=run_mtmc(cams_dir=cams_dir_, weights=weights_, imgsz=imgsz_, cams_ratio=cams_ratio_, lazy_threshold=lazy_threshold_)
  File "/data1/xiayuyang/online_mcmt/detector/yolov5/my_mtmc.py", line 792, in run_mtmc
    g_tid += 1
UnboundLocalError: local variable 'g_tid' referenced before assignment

config: Configuration(values={
  'fps_camera1': '10',
  'fps_camera2': '2',
  'fps_camera3': '10',
  'fps_camera4': '1',
  'fps_camera5': '2',
  'lazy_threshold': 0.6799999999999999,
  'model_size_camera1': 'yolov5l.pt',
  'model_size_camera2': 'yolov5l.pt',
  'model_size_camera3': 'yolov5s.pt',
  'model_size_camera4': 'yolov5s.pt',
  'model_size_camera5': 'yolov5s.pt',
  'resolution_camera1': '320',
  'resolution_camera2': '1280',
  'resolution_camera3': '1280',
  'resolution_camera4': '320',
  'resolution_camera5': '1280',
})

[2024-01-23 23:47:39,882][0][INFO][generic_smbo.py:295] Iter 28, objectives: [inf, inf].
[2024-01-23 23:47:39,885][0][WARNING][generic_advisor.py:375] No enough successful initial trials! Sample random configuration.
[2024-01-23 23:48:17,427][0][ERROR][generic_smbo.py:275] Exception in objective function:
Traceback (most recent call last):
  File "/data1/xiayuyang/anaconda3/envs/carla/lib/python3.8/site-packages/openbox/utils/limit.py", line 62, in run_without_time_limit
    ret = obj_func(*obj_args, **obj_kwargs)
  File "/data1/xiayuyang/online_mcmt/detector/yolov5/bo.py", line 80, in multi_camera_matching
    accuracy, processing_time = profile(
  File "/data1/xiayuyang/online_mcmt/detector/yolov5/my_mtmc.py", line 910, in profile
    gt_detect, gt_dict, total_detect_time, total_extract_time, total_sct_time, total_pp_time, total_match_time=run_mtmc(cams_dir=cams_dir_, weights=weights_, imgsz=imgsz_, cams_ratio=cams_ratio_, lazy_threshold=lazy_threshold_)
  File "/data1/xiayuyang/online_mcmt/detector/yolov5/my_mtmc.py", line 792, in run_mtmc
    g_tid += 1
UnboundLocalError: local variable 'g_tid' referenced before assignment

config: Configuration(values={
  'fps_camera1': '4',
  'fps_camera2': '4',
  'fps_camera3': '1',
  'fps_camera4': '1',
  'fps_camera5': '4',
  'lazy_threshold': 0.84,
  'model_size_camera1': 'yolov5m.pt',
  'model_size_camera2': 'yolov5s.pt',
  'model_size_camera3': 'yolov5s.pt',
  'model_size_camera4': 'yolov5m.pt',
  'model_size_camera5': 'yolov5m.pt',
  'resolution_camera1': '1280',
  'resolution_camera2': '1280',
  'resolution_camera3': '640',
  'resolution_camera4': '1280',
  'resolution_camera5': '640',
})

[2024-01-23 23:48:17,428][0][INFO][generic_smbo.py:295] Iter 29, objectives: [inf, inf].
[2024-01-23 23:48:17,430][0][WARNING][generic_advisor.py:375] No enough successful initial trials! Sample random configuration.
[2024-01-23 23:48:43,890][0][ERROR][generic_smbo.py:275] Exception in objective function:
Traceback (most recent call last):
  File "/data1/xiayuyang/anaconda3/envs/carla/lib/python3.8/site-packages/openbox/utils/limit.py", line 62, in run_without_time_limit
    ret = obj_func(*obj_args, **obj_kwargs)
  File "/data1/xiayuyang/online_mcmt/detector/yolov5/bo.py", line 80, in multi_camera_matching
    accuracy, processing_time = profile(
  File "/data1/xiayuyang/online_mcmt/detector/yolov5/my_mtmc.py", line 910, in profile
    gt_detect, gt_dict, total_detect_time, total_extract_time, total_sct_time, total_pp_time, total_match_time=run_mtmc(cams_dir=cams_dir_, weights=weights_, imgsz=imgsz_, cams_ratio=cams_ratio_, lazy_threshold=lazy_threshold_)
  File "/data1/xiayuyang/online_mcmt/detector/yolov5/my_mtmc.py", line 792, in run_mtmc
    g_tid += 1
UnboundLocalError: local variable 'g_tid' referenced before assignment

config: Configuration(values={
  'fps_camera1': '10',
  'fps_camera2': '2',
  'fps_camera3': '2',
  'fps_camera4': '1',
  'fps_camera5': '2',
  'lazy_threshold': 0.8,
  'model_size_camera1': 'yolov5m.pt',
  'model_size_camera2': 'yolov5s.pt',
  'model_size_camera3': 'yolov5l.pt',
  'model_size_camera4': 'yolov5s.pt',
  'model_size_camera5': 'yolov5s.pt',
  'resolution_camera1': '320',
  'resolution_camera2': '320',
  'resolution_camera3': '1280',
  'resolution_camera4': '640',
  'resolution_camera5': '1280',
})

[2024-01-23 23:48:43,891][0][INFO][generic_smbo.py:295] Iter 30, objectives: [inf, inf].
[2024-01-23 23:48:43,893][0][WARNING][generic_advisor.py:375] No enough successful initial trials! Sample random configuration.
[2024-01-23 23:49:17,455][0][ERROR][generic_smbo.py:275] Exception in objective function:
Traceback (most recent call last):
  File "/data1/xiayuyang/anaconda3/envs/carla/lib/python3.8/site-packages/openbox/utils/limit.py", line 62, in run_without_time_limit
    ret = obj_func(*obj_args, **obj_kwargs)
  File "/data1/xiayuyang/online_mcmt/detector/yolov5/bo.py", line 80, in multi_camera_matching
    accuracy, processing_time = profile(
  File "/data1/xiayuyang/online_mcmt/detector/yolov5/my_mtmc.py", line 910, in profile
    gt_detect, gt_dict, total_detect_time, total_extract_time, total_sct_time, total_pp_time, total_match_time=run_mtmc(cams_dir=cams_dir_, weights=weights_, imgsz=imgsz_, cams_ratio=cams_ratio_, lazy_threshold=lazy_threshold_)
  File "/data1/xiayuyang/online_mcmt/detector/yolov5/my_mtmc.py", line 792, in run_mtmc
    g_tid += 1
UnboundLocalError: local variable 'g_tid' referenced before assignment

config: Configuration(values={
  'fps_camera1': '1',
  'fps_camera2': '4',
  'fps_camera3': '10',
  'fps_camera4': '1',
  'fps_camera5': '4',
  'lazy_threshold': 0.64,
  'model_size_camera1': 'yolov5m.pt',
  'model_size_camera2': 'yolov5s.pt',
  'model_size_camera3': 'yolov5l.pt',
  'model_size_camera4': 'yolov5s.pt',
  'model_size_camera5': 'yolov5l.pt',
  'resolution_camera1': '1280',
  'resolution_camera2': '640',
  'resolution_camera3': '1280',
  'resolution_camera4': '320',
  'resolution_camera5': '640',
})

[2024-01-23 23:49:17,456][0][INFO][generic_smbo.py:295] Iter 31, objectives: [inf, inf].
[2024-01-23 23:49:17,457][0][WARNING][generic_advisor.py:375] No enough successful initial trials! Sample random configuration.
[2024-01-23 23:49:51,270][0][ERROR][generic_smbo.py:275] Exception in objective function:
Traceback (most recent call last):
  File "/data1/xiayuyang/anaconda3/envs/carla/lib/python3.8/site-packages/openbox/utils/limit.py", line 62, in run_without_time_limit
    ret = obj_func(*obj_args, **obj_kwargs)
  File "/data1/xiayuyang/online_mcmt/detector/yolov5/bo.py", line 80, in multi_camera_matching
    accuracy, processing_time = profile(
  File "/data1/xiayuyang/online_mcmt/detector/yolov5/my_mtmc.py", line 910, in profile
    gt_detect, gt_dict, total_detect_time, total_extract_time, total_sct_time, total_pp_time, total_match_time=run_mtmc(cams_dir=cams_dir_, weights=weights_, imgsz=imgsz_, cams_ratio=cams_ratio_, lazy_threshold=lazy_threshold_)
  File "/data1/xiayuyang/online_mcmt/detector/yolov5/my_mtmc.py", line 792, in run_mtmc
    g_tid += 1
UnboundLocalError: local variable 'g_tid' referenced before assignment

config: Configuration(values={
  'fps_camera1': '4',
  'fps_camera2': '4',
  'fps_camera3': '1',
  'fps_camera4': '2',
  'fps_camera5': '4',
  'lazy_threshold': 0.64,
  'model_size_camera1': 'yolov5s.pt',
  'model_size_camera2': 'yolov5l.pt',
  'model_size_camera3': 'yolov5l.pt',
  'model_size_camera4': 'yolov5m.pt',
  'model_size_camera5': 'yolov5l.pt',
  'resolution_camera1': '320',
  'resolution_camera2': '320',
  'resolution_camera3': '320',
  'resolution_camera4': '320',
  'resolution_camera5': '1280',
})

[2024-01-23 23:49:51,272][0][INFO][generic_smbo.py:295] Iter 32, objectives: [inf, inf].
[2024-01-23 23:49:51,274][0][WARNING][generic_advisor.py:375] No enough successful initial trials! Sample random configuration.
[2024-01-23 23:50:32,471][0][ERROR][generic_smbo.py:275] Exception in objective function:
Traceback (most recent call last):
  File "/data1/xiayuyang/anaconda3/envs/carla/lib/python3.8/site-packages/openbox/utils/limit.py", line 62, in run_without_time_limit
    ret = obj_func(*obj_args, **obj_kwargs)
  File "/data1/xiayuyang/online_mcmt/detector/yolov5/bo.py", line 80, in multi_camera_matching
    accuracy, processing_time = profile(
  File "/data1/xiayuyang/online_mcmt/detector/yolov5/my_mtmc.py", line 910, in profile
    gt_detect, gt_dict, total_detect_time, total_extract_time, total_sct_time, total_pp_time, total_match_time=run_mtmc(cams_dir=cams_dir_, weights=weights_, imgsz=imgsz_, cams_ratio=cams_ratio_, lazy_threshold=lazy_threshold_)
  File "/data1/xiayuyang/online_mcmt/detector/yolov5/my_mtmc.py", line 792, in run_mtmc
    g_tid += 1
UnboundLocalError: local variable 'g_tid' referenced before assignment

config: Configuration(values={
  'fps_camera1': '1',
  'fps_camera2': '4',
  'fps_camera3': '4',
  'fps_camera4': '1',
  'fps_camera5': '10',
  'lazy_threshold': 0.78,
  'model_size_camera1': 'yolov5l.pt',
  'model_size_camera2': 'yolov5s.pt',
  'model_size_camera3': 'yolov5m.pt',
  'model_size_camera4': 'yolov5m.pt',
  'model_size_camera5': 'yolov5l.pt',
  'resolution_camera1': '1280',
  'resolution_camera2': '320',
  'resolution_camera3': '320',
  'resolution_camera4': '640',
  'resolution_camera5': '1280',
})

[2024-01-23 23:50:32,472][0][INFO][generic_smbo.py:295] Iter 33, objectives: [inf, inf].
[2024-01-23 23:50:32,475][0][WARNING][generic_advisor.py:375] No enough successful initial trials! Sample random configuration.
[2024-01-23 23:50:49,888][0][ERROR][generic_smbo.py:275] Exception in objective function:
Traceback (most recent call last):
  File "/data1/xiayuyang/anaconda3/envs/carla/lib/python3.8/site-packages/openbox/utils/limit.py", line 62, in run_without_time_limit
    ret = obj_func(*obj_args, **obj_kwargs)
  File "/data1/xiayuyang/online_mcmt/detector/yolov5/bo.py", line 80, in multi_camera_matching
    accuracy, processing_time = profile(
  File "/data1/xiayuyang/online_mcmt/detector/yolov5/my_mtmc.py", line 910, in profile
    gt_detect, gt_dict, total_detect_time, total_extract_time, total_sct_time, total_pp_time, total_match_time=run_mtmc(cams_dir=cams_dir_, weights=weights_, imgsz=imgsz_, cams_ratio=cams_ratio_, lazy_threshold=lazy_threshold_)
  File "/data1/xiayuyang/online_mcmt/detector/yolov5/my_mtmc.py", line 792, in run_mtmc
    g_tid += 1
UnboundLocalError: local variable 'g_tid' referenced before assignment

config: Configuration(values={
  'fps_camera1': '2',
  'fps_camera2': '10',
  'fps_camera3': '4',
  'fps_camera4': '4',
  'fps_camera5': '10',
  'lazy_threshold': 0.74,
  'model_size_camera1': 'yolov5m.pt',
  'model_size_camera2': 'yolov5m.pt',
  'model_size_camera3': 'yolov5m.pt',
  'model_size_camera4': 'yolov5m.pt',
  'model_size_camera5': 'yolov5s.pt',
  'resolution_camera1': '320',
  'resolution_camera2': '640',
  'resolution_camera3': '320',
  'resolution_camera4': '320',
  'resolution_camera5': '1280',
})

[2024-01-23 23:50:49,889][0][INFO][generic_smbo.py:295] Iter 34, objectives: [inf, inf].
[2024-01-23 23:50:49,891][0][WARNING][generic_advisor.py:375] No enough successful initial trials! Sample random configuration.
[2024-01-23 23:51:25,169][0][ERROR][generic_smbo.py:275] Exception in objective function:
Traceback (most recent call last):
  File "/data1/xiayuyang/anaconda3/envs/carla/lib/python3.8/site-packages/openbox/utils/limit.py", line 62, in run_without_time_limit
    ret = obj_func(*obj_args, **obj_kwargs)
  File "/data1/xiayuyang/online_mcmt/detector/yolov5/bo.py", line 80, in multi_camera_matching
    accuracy, processing_time = profile(
  File "/data1/xiayuyang/online_mcmt/detector/yolov5/my_mtmc.py", line 910, in profile
    gt_detect, gt_dict, total_detect_time, total_extract_time, total_sct_time, total_pp_time, total_match_time=run_mtmc(cams_dir=cams_dir_, weights=weights_, imgsz=imgsz_, cams_ratio=cams_ratio_, lazy_threshold=lazy_threshold_)
  File "/data1/xiayuyang/online_mcmt/detector/yolov5/my_mtmc.py", line 792, in run_mtmc
    g_tid += 1
UnboundLocalError: local variable 'g_tid' referenced before assignment

config: Configuration(values={
  'fps_camera1': '10',
  'fps_camera2': '2',
  'fps_camera3': '10',
  'fps_camera4': '1',
  'fps_camera5': '10',
  'lazy_threshold': 0.78,
  'model_size_camera1': 'yolov5s.pt',
  'model_size_camera2': 'yolov5m.pt',
  'model_size_camera3': 'yolov5l.pt',
  'model_size_camera4': 'yolov5m.pt',
  'model_size_camera5': 'yolov5m.pt',
  'resolution_camera1': '640',
  'resolution_camera2': '1280',
  'resolution_camera3': '1280',
  'resolution_camera4': '1280',
  'resolution_camera5': '640',
})

[2024-01-23 23:51:25,170][0][INFO][generic_smbo.py:295] Iter 35, objectives: [inf, inf].
[2024-01-23 23:51:25,172][0][WARNING][generic_advisor.py:375] No enough successful initial trials! Sample random configuration.
[2024-01-23 23:51:50,833][0][ERROR][generic_smbo.py:275] Exception in objective function:
Traceback (most recent call last):
  File "/data1/xiayuyang/anaconda3/envs/carla/lib/python3.8/site-packages/openbox/utils/limit.py", line 62, in run_without_time_limit
    ret = obj_func(*obj_args, **obj_kwargs)
  File "/data1/xiayuyang/online_mcmt/detector/yolov5/bo.py", line 80, in multi_camera_matching
    accuracy, processing_time = profile(
  File "/data1/xiayuyang/online_mcmt/detector/yolov5/my_mtmc.py", line 910, in profile
    gt_detect, gt_dict, total_detect_time, total_extract_time, total_sct_time, total_pp_time, total_match_time=run_mtmc(cams_dir=cams_dir_, weights=weights_, imgsz=imgsz_, cams_ratio=cams_ratio_, lazy_threshold=lazy_threshold_)
  File "/data1/xiayuyang/online_mcmt/detector/yolov5/my_mtmc.py", line 792, in run_mtmc
    g_tid += 1
UnboundLocalError: local variable 'g_tid' referenced before assignment

config: Configuration(values={
  'fps_camera1': '2',
  'fps_camera2': '1',
  'fps_camera3': '2',
  'fps_camera4': '4',
  'fps_camera5': '10',
  'lazy_threshold': 0.7,
  'model_size_camera1': 'yolov5l.pt',
  'model_size_camera2': 'yolov5s.pt',
  'model_size_camera3': 'yolov5l.pt',
  'model_size_camera4': 'yolov5l.pt',
  'model_size_camera5': 'yolov5m.pt',
  'resolution_camera1': '320',
  'resolution_camera2': '1280',
  'resolution_camera3': '640',
  'resolution_camera4': '1280',
  'resolution_camera5': '320',
})

[2024-01-23 23:51:50,835][0][INFO][generic_smbo.py:295] Iter 36, objectives: [inf, inf].
[2024-01-23 23:51:50,837][0][WARNING][generic_advisor.py:375] No enough successful initial trials! Sample random configuration.
[2024-01-23 23:52:17,248][0][ERROR][generic_smbo.py:275] Exception in objective function:
Traceback (most recent call last):
  File "/data1/xiayuyang/anaconda3/envs/carla/lib/python3.8/site-packages/openbox/utils/limit.py", line 62, in run_without_time_limit
    ret = obj_func(*obj_args, **obj_kwargs)
  File "/data1/xiayuyang/online_mcmt/detector/yolov5/bo.py", line 80, in multi_camera_matching
    accuracy, processing_time = profile(
  File "/data1/xiayuyang/online_mcmt/detector/yolov5/my_mtmc.py", line 910, in profile
    gt_detect, gt_dict, total_detect_time, total_extract_time, total_sct_time, total_pp_time, total_match_time=run_mtmc(cams_dir=cams_dir_, weights=weights_, imgsz=imgsz_, cams_ratio=cams_ratio_, lazy_threshold=lazy_threshold_)
  File "/data1/xiayuyang/online_mcmt/detector/yolov5/my_mtmc.py", line 792, in run_mtmc
    g_tid += 1
UnboundLocalError: local variable 'g_tid' referenced before assignment

config: Configuration(values={
  'fps_camera1': '1',
  'fps_camera2': '2',
  'fps_camera3': '1',
  'fps_camera4': '2',
  'fps_camera5': '10',
  'lazy_threshold': 0.74,
  'model_size_camera1': 'yolov5s.pt',
  'model_size_camera2': 'yolov5l.pt',
  'model_size_camera3': 'yolov5l.pt',
  'model_size_camera4': 'yolov5l.pt',
  'model_size_camera5': 'yolov5l.pt',
  'resolution_camera1': '640',
  'resolution_camera2': '1280',
  'resolution_camera3': '640',
  'resolution_camera4': '320',
  'resolution_camera5': '1280',
})

[2024-01-23 23:52:17,249][0][INFO][generic_smbo.py:295] Iter 37, objectives: [inf, inf].
[2024-01-23 23:52:17,251][0][WARNING][generic_advisor.py:375] No enough successful initial trials! Sample random configuration.
[2024-01-23 23:52:39,868][0][ERROR][generic_smbo.py:275] Exception in objective function:
Traceback (most recent call last):
  File "/data1/xiayuyang/anaconda3/envs/carla/lib/python3.8/site-packages/openbox/utils/limit.py", line 62, in run_without_time_limit
    ret = obj_func(*obj_args, **obj_kwargs)
  File "/data1/xiayuyang/online_mcmt/detector/yolov5/bo.py", line 80, in multi_camera_matching
    accuracy, processing_time = profile(
  File "/data1/xiayuyang/online_mcmt/detector/yolov5/my_mtmc.py", line 910, in profile
    gt_detect, gt_dict, total_detect_time, total_extract_time, total_sct_time, total_pp_time, total_match_time=run_mtmc(cams_dir=cams_dir_, weights=weights_, imgsz=imgsz_, cams_ratio=cams_ratio_, lazy_threshold=lazy_threshold_)
  File "/data1/xiayuyang/online_mcmt/detector/yolov5/my_mtmc.py", line 792, in run_mtmc
    g_tid += 1
UnboundLocalError: local variable 'g_tid' referenced before assignment

config: Configuration(values={
  'fps_camera1': '4',
  'fps_camera2': '2',
  'fps_camera3': '1',
  'fps_camera4': '10',
  'fps_camera5': '4',
  'lazy_threshold': 0.64,
  'model_size_camera1': 'yolov5m.pt',
  'model_size_camera2': 'yolov5s.pt',
  'model_size_camera3': 'yolov5l.pt',
  'model_size_camera4': 'yolov5l.pt',
  'model_size_camera5': 'yolov5l.pt',
  'resolution_camera1': '320',
  'resolution_camera2': '1280',
  'resolution_camera3': '320',
  'resolution_camera4': '640',
  'resolution_camera5': '320',
})

[2024-01-23 23:52:39,870][0][INFO][generic_smbo.py:295] Iter 38, objectives: [inf, inf].
[2024-01-23 23:52:39,872][0][WARNING][generic_advisor.py:375] No enough successful initial trials! Sample random configuration.
[2024-01-23 23:53:16,037][0][ERROR][generic_smbo.py:275] Exception in objective function:
Traceback (most recent call last):
  File "/data1/xiayuyang/anaconda3/envs/carla/lib/python3.8/site-packages/openbox/utils/limit.py", line 62, in run_without_time_limit
    ret = obj_func(*obj_args, **obj_kwargs)
  File "/data1/xiayuyang/online_mcmt/detector/yolov5/bo.py", line 80, in multi_camera_matching
    accuracy, processing_time = profile(
  File "/data1/xiayuyang/online_mcmt/detector/yolov5/my_mtmc.py", line 910, in profile
    gt_detect, gt_dict, total_detect_time, total_extract_time, total_sct_time, total_pp_time, total_match_time=run_mtmc(cams_dir=cams_dir_, weights=weights_, imgsz=imgsz_, cams_ratio=cams_ratio_, lazy_threshold=lazy_threshold_)
  File "/data1/xiayuyang/online_mcmt/detector/yolov5/my_mtmc.py", line 792, in run_mtmc
    g_tid += 1
UnboundLocalError: local variable 'g_tid' referenced before assignment

config: Configuration(values={
  'fps_camera1': '4',
  'fps_camera2': '4',
  'fps_camera3': '1',
  'fps_camera4': '10',
  'fps_camera5': '1',
  'lazy_threshold': 0.7,
  'model_size_camera1': 'yolov5l.pt',
  'model_size_camera2': 'yolov5s.pt',
  'model_size_camera3': 'yolov5m.pt',
  'model_size_camera4': 'yolov5m.pt',
  'model_size_camera5': 'yolov5m.pt',
  'resolution_camera1': '640',
  'resolution_camera2': '640',
  'resolution_camera3': '640',
  'resolution_camera4': '640',
  'resolution_camera5': '640',
})

[2024-01-23 23:53:16,039][0][INFO][generic_smbo.py:295] Iter 39, objectives: [inf, inf].
[2024-01-23 23:53:16,041][0][WARNING][generic_advisor.py:375] No enough successful initial trials! Sample random configuration.
[2024-01-23 23:53:33,381][0][ERROR][generic_smbo.py:275] Exception in objective function:
Traceback (most recent call last):
  File "/data1/xiayuyang/anaconda3/envs/carla/lib/python3.8/site-packages/openbox/utils/limit.py", line 62, in run_without_time_limit
    ret = obj_func(*obj_args, **obj_kwargs)
  File "/data1/xiayuyang/online_mcmt/detector/yolov5/bo.py", line 80, in multi_camera_matching
    accuracy, processing_time = profile(
  File "/data1/xiayuyang/online_mcmt/detector/yolov5/my_mtmc.py", line 910, in profile
    gt_detect, gt_dict, total_detect_time, total_extract_time, total_sct_time, total_pp_time, total_match_time=run_mtmc(cams_dir=cams_dir_, weights=weights_, imgsz=imgsz_, cams_ratio=cams_ratio_, lazy_threshold=lazy_threshold_)
  File "/data1/xiayuyang/online_mcmt/detector/yolov5/my_mtmc.py", line 792, in run_mtmc
    g_tid += 1
UnboundLocalError: local variable 'g_tid' referenced before assignment

config: Configuration(values={
  'fps_camera1': '10',
  'fps_camera2': '1',
  'fps_camera3': '4',
  'fps_camera4': '4',
  'fps_camera5': '10',
  'lazy_threshold': 0.62,
  'model_size_camera1': 'yolov5m.pt',
  'model_size_camera2': 'yolov5s.pt',
  'model_size_camera3': 'yolov5l.pt',
  'model_size_camera4': 'yolov5s.pt',
  'model_size_camera5': 'yolov5s.pt',
  'resolution_camera1': '640',
  'resolution_camera2': '320',
  'resolution_camera3': '1280',
  'resolution_camera4': '640',
  'resolution_camera5': '320',
})

[2024-01-23 23:53:33,382][0][INFO][generic_smbo.py:295] Iter 40, objectives: [inf, inf].
[2024-01-23 23:53:33,384][0][WARNING][generic_advisor.py:375] No enough successful initial trials! Sample random configuration.
[2024-01-23 23:54:14,498][0][ERROR][generic_smbo.py:275] Exception in objective function:
Traceback (most recent call last):
  File "/data1/xiayuyang/anaconda3/envs/carla/lib/python3.8/site-packages/openbox/utils/limit.py", line 62, in run_without_time_limit
    ret = obj_func(*obj_args, **obj_kwargs)
  File "/data1/xiayuyang/online_mcmt/detector/yolov5/bo.py", line 80, in multi_camera_matching
    accuracy, processing_time = profile(
  File "/data1/xiayuyang/online_mcmt/detector/yolov5/my_mtmc.py", line 910, in profile
    gt_detect, gt_dict, total_detect_time, total_extract_time, total_sct_time, total_pp_time, total_match_time=run_mtmc(cams_dir=cams_dir_, weights=weights_, imgsz=imgsz_, cams_ratio=cams_ratio_, lazy_threshold=lazy_threshold_)
  File "/data1/xiayuyang/online_mcmt/detector/yolov5/my_mtmc.py", line 792, in run_mtmc
    g_tid += 1
UnboundLocalError: local variable 'g_tid' referenced before assignment

config: Configuration(values={
  'fps_camera1': '10',
  'fps_camera2': '2',
  'fps_camera3': '2',
  'fps_camera4': '1',
  'fps_camera5': '10',
  'lazy_threshold': 0.64,
  'model_size_camera1': 'yolov5l.pt',
  'model_size_camera2': 'yolov5m.pt',
  'model_size_camera3': 'yolov5m.pt',
  'model_size_camera4': 'yolov5l.pt',
  'model_size_camera5': 'yolov5l.pt',
  'resolution_camera1': '640',
  'resolution_camera2': '1280',
  'resolution_camera3': '1280',
  'resolution_camera4': '1280',
  'resolution_camera5': '640',
})

[2024-01-23 23:54:14,499][0][INFO][generic_smbo.py:295] Iter 41, objectives: [inf, inf].
[2024-01-23 23:54:14,502][0][WARNING][generic_advisor.py:375] No enough successful initial trials! Sample random configuration.
[2024-01-23 23:54:33,043][0][ERROR][generic_smbo.py:275] Exception in objective function:
Traceback (most recent call last):
  File "/data1/xiayuyang/anaconda3/envs/carla/lib/python3.8/site-packages/openbox/utils/limit.py", line 62, in run_without_time_limit
    ret = obj_func(*obj_args, **obj_kwargs)
  File "/data1/xiayuyang/online_mcmt/detector/yolov5/bo.py", line 80, in multi_camera_matching
    accuracy, processing_time = profile(
  File "/data1/xiayuyang/online_mcmt/detector/yolov5/my_mtmc.py", line 910, in profile
    gt_detect, gt_dict, total_detect_time, total_extract_time, total_sct_time, total_pp_time, total_match_time=run_mtmc(cams_dir=cams_dir_, weights=weights_, imgsz=imgsz_, cams_ratio=cams_ratio_, lazy_threshold=lazy_threshold_)
  File "/data1/xiayuyang/online_mcmt/detector/yolov5/my_mtmc.py", line 792, in run_mtmc
    g_tid += 1
UnboundLocalError: local variable 'g_tid' referenced before assignment

config: Configuration(values={
  'fps_camera1': '10',
  'fps_camera2': '1',
  'fps_camera3': '4',
  'fps_camera4': '2',
  'fps_camera5': '10',
  'lazy_threshold': 0.7,
  'model_size_camera1': 'yolov5l.pt',
  'model_size_camera2': 'yolov5s.pt',
  'model_size_camera3': 'yolov5l.pt',
  'model_size_camera4': 'yolov5m.pt',
  'model_size_camera5': 'yolov5m.pt',
  'resolution_camera1': '320',
  'resolution_camera2': '320',
  'resolution_camera3': '1280',
  'resolution_camera4': '320',
  'resolution_camera5': '320',
})

[2024-01-23 23:54:33,046][0][INFO][generic_smbo.py:295] Iter 42, objectives: [inf, inf].
[2024-01-23 23:54:33,050][0][WARNING][generic_advisor.py:375] No enough successful initial trials! Sample random configuration.
[2024-01-23 23:54:57,774][0][ERROR][generic_smbo.py:275] Exception in objective function:
Traceback (most recent call last):
  File "/data1/xiayuyang/anaconda3/envs/carla/lib/python3.8/site-packages/openbox/utils/limit.py", line 62, in run_without_time_limit
    ret = obj_func(*obj_args, **obj_kwargs)
  File "/data1/xiayuyang/online_mcmt/detector/yolov5/bo.py", line 80, in multi_camera_matching
    accuracy, processing_time = profile(
  File "/data1/xiayuyang/online_mcmt/detector/yolov5/my_mtmc.py", line 910, in profile
    gt_detect, gt_dict, total_detect_time, total_extract_time, total_sct_time, total_pp_time, total_match_time=run_mtmc(cams_dir=cams_dir_, weights=weights_, imgsz=imgsz_, cams_ratio=cams_ratio_, lazy_threshold=lazy_threshold_)
  File "/data1/xiayuyang/online_mcmt/detector/yolov5/my_mtmc.py", line 792, in run_mtmc
    g_tid += 1
UnboundLocalError: local variable 'g_tid' referenced before assignment

config: Configuration(values={
  'fps_camera1': '10',
  'fps_camera2': '4',
  'fps_camera3': '10',
  'fps_camera4': '4',
  'fps_camera5': '10',
  'lazy_threshold': 0.82,
  'model_size_camera1': 'yolov5s.pt',
  'model_size_camera2': 'yolov5m.pt',
  'model_size_camera3': 'yolov5l.pt',
  'model_size_camera4': 'yolov5m.pt',
  'model_size_camera5': 'yolov5l.pt',
  'resolution_camera1': '320',
  'resolution_camera2': '1280',
  'resolution_camera3': '1280',
  'resolution_camera4': '1280',
  'resolution_camera5': '1280',
})

[2024-01-23 23:54:57,775][0][INFO][generic_smbo.py:295] Iter 43, objectives: [inf, inf].
[2024-01-23 23:54:57,777][0][WARNING][generic_advisor.py:375] No enough successful initial trials! Sample random configuration.
[2024-01-23 23:55:30,523][0][ERROR][generic_smbo.py:275] Exception in objective function:
Traceback (most recent call last):
  File "/data1/xiayuyang/anaconda3/envs/carla/lib/python3.8/site-packages/openbox/utils/limit.py", line 62, in run_without_time_limit
    ret = obj_func(*obj_args, **obj_kwargs)
  File "/data1/xiayuyang/online_mcmt/detector/yolov5/bo.py", line 80, in multi_camera_matching
    accuracy, processing_time = profile(
  File "/data1/xiayuyang/online_mcmt/detector/yolov5/my_mtmc.py", line 910, in profile
    gt_detect, gt_dict, total_detect_time, total_extract_time, total_sct_time, total_pp_time, total_match_time=run_mtmc(cams_dir=cams_dir_, weights=weights_, imgsz=imgsz_, cams_ratio=cams_ratio_, lazy_threshold=lazy_threshold_)
  File "/data1/xiayuyang/online_mcmt/detector/yolov5/my_mtmc.py", line 792, in run_mtmc
    g_tid += 1
UnboundLocalError: local variable 'g_tid' referenced before assignment

config: Configuration(values={
  'fps_camera1': '4',
  'fps_camera2': '10',
  'fps_camera3': '1',
  'fps_camera4': '1',
  'fps_camera5': '1',
  'lazy_threshold': 0.86,
  'model_size_camera1': 'yolov5l.pt',
  'model_size_camera2': 'yolov5l.pt',
  'model_size_camera3': 'yolov5s.pt',
  'model_size_camera4': 'yolov5l.pt',
  'model_size_camera5': 'yolov5m.pt',
  'resolution_camera1': '320',
  'resolution_camera2': '320',
  'resolution_camera3': '640',
  'resolution_camera4': '640',
  'resolution_camera5': '320',
})

[2024-01-23 23:55:30,525][0][INFO][generic_smbo.py:295] Iter 44, objectives: [inf, inf].
[2024-01-23 23:55:30,528][0][INFO][generic_advisor.py:365] Sample random config. rand_prob=0.100000.
[2024-01-23 23:55:57,514][0][ERROR][generic_smbo.py:275] Exception in objective function:
Traceback (most recent call last):
  File "/data1/xiayuyang/anaconda3/envs/carla/lib/python3.8/site-packages/openbox/utils/limit.py", line 62, in run_without_time_limit
    ret = obj_func(*obj_args, **obj_kwargs)
  File "/data1/xiayuyang/online_mcmt/detector/yolov5/bo.py", line 80, in multi_camera_matching
    accuracy, processing_time = profile(
  File "/data1/xiayuyang/online_mcmt/detector/yolov5/my_mtmc.py", line 910, in profile
    gt_detect, gt_dict, total_detect_time, total_extract_time, total_sct_time, total_pp_time, total_match_time=run_mtmc(cams_dir=cams_dir_, weights=weights_, imgsz=imgsz_, cams_ratio=cams_ratio_, lazy_threshold=lazy_threshold_)
  File "/data1/xiayuyang/online_mcmt/detector/yolov5/my_mtmc.py", line 792, in run_mtmc
    g_tid += 1
UnboundLocalError: local variable 'g_tid' referenced before assignment

config: Configuration(values={
  'fps_camera1': '2',
  'fps_camera2': '4',
  'fps_camera3': '4',
  'fps_camera4': '4',
  'fps_camera5': '4',
  'lazy_threshold': 0.72,
  'model_size_camera1': 'yolov5s.pt',
  'model_size_camera2': 'yolov5s.pt',
  'model_size_camera3': 'yolov5m.pt',
  'model_size_camera4': 'yolov5s.pt',
  'model_size_camera5': 'yolov5l.pt',
  'resolution_camera1': '1280',
  'resolution_camera2': '320',
  'resolution_camera3': '640',
  'resolution_camera4': '320',
  'resolution_camera5': '1280',
})

[2024-01-23 23:55:57,515][0][INFO][generic_smbo.py:295] Iter 45, objectives: [inf, inf].
[2024-01-23 23:55:57,517][0][WARNING][generic_advisor.py:375] No enough successful initial trials! Sample random configuration.
